Workbook

Sheet Summary
A1: SimQ Run 2: Weekly 1% Summary
A2: Paper-trading simulation of cash-secured puts and covered calls on SimQ (a synthetic 3x leveraged index). Week-by-week detail is on the Weekly and Trades tabs.
I3: Chart: account end value each week (blue), the 1% weekly target path (red dashed), buy-and-hold SimQ (grey), and cash-only (green). Data: Weekly tab columns N, S, V, W.
A4: Assumptions
B5: Starting cash ($) | C5: 7500 | D5: Run rules: identical start for every run
B6: Interest on idle cash (APY) | C6: 0.04 | D6: Run rules: simple daily accrual, actual/365
B7: Weekly return target | C7: 0.01 | D7: The "weekly 1%" goal being tested (change this to test another target)
B8: SimQ starting price ($) | C8: 63.8 | D8: Run rules: SimQ at $63.80 on Week 1 open
A10: Results
B11: Start | C11: Week 26 | D11: Week 52 | E11: Start → Week 26 | F11: Week 26 → Week 52 | G11: Full year
A12: Account value ($) (period cols = $ change) | B12: =$C$5 -> 7500 | C12: =INDEX(Weekly!$N$2:$N$53,26) -> 9189.18 | D12: =INDEX(Weekly!$N$2:$N$53,52) -> 11924.36 | E12: =C12-B12 -> 1689.18 | F12: =D12-C12 -> 2735.18 | G12: =D12-B12 -> 4424.36
A13: Return since start | C13: =C12/B12-1 -> 0.225224 | D13: =D12/B12-1 -> 0.58991467
A14: Avg weekly return (compounded) | E14: =(C12/B12)^(1/26)-1 -> 0.0078430462 | F14: =(D12/C12)^(1/26)-1 -> 0.010071793 | G14: =(D12/B12)^(1/52)-1 -> 0.008956804
A15: 1% weekly target value ($) | B15: =$C$5 -> 7500 | C15: =$C$5*(1+$C$7)^26 -> 9714.4224 | D15: =$C$5*(1+$C$7)^52 -> 12582.667
A16: Ahead / behind 1% target ($) | C16: =C12-C15 -> -525.24236 | D16: =D12-D15 -> -658.30691
A17: SimQ price (period cols = % change) | B17: =$C$8 -> 63.8 | C17: =INDEX(Weekly!$D$2:$D$53,26) -> 92.15 | D17: =INDEX(Weekly!$D$2:$D$53,52) -> 64.67 | E17: =C17/B17-1 -> 0.44435737 | F17: =D17/C17-1 -> -0.29820944 | G17: =D17/B17-1 -> 0.013636364
A18: Buy-and-hold SimQ value ($) | B18: =$C$5 -> 7500 | C18: =$C$5*C17/$C$8 -> 10832.68 | D18: =$C$5*D17/$C$8 -> 7602.2727
A19: Cash-only value at APY ($) | B19: =$C$5 -> 7500 | C19: =$C$5*(1+$C$6*182/365) -> 7649.589 | D19: =$C$5*(1+$C$6*364/365) -> 7799.1781
A20: Premium collected ($) | E20: =SUM(Weekly!H2:H27) -> 2315 | F20: =SUM(Weekly!H28:H53) -> 3385 | G20: =SUM(Weekly!H2:H53) -> 5700
A21: Buy-backs paid ($) | E21: =SUM(Weekly!I2:I27) -> 1212 | F21: =SUM(Weekly!I28:I53) -> 1536 | G21: =SUM(Weekly!I2:I53) -> 2748
A22: Options net ($) | E22: =SUM(Weekly!J2:J27) -> 1103 | F22: =SUM(Weekly!J28:J53) -> 1849 | G22: =SUM(Weekly!J2:J53) -> 2952
A23: Share P&L ($) | E23: =SUM(Weekly!K2:K27) -> 450 | F23: =SUM(Weekly!K28:K53) -> 700 | G23: =SUM(Weekly!K2:K53) -> 1150
A24: Interest ($) | E24: =SUM(Weekly!L2:L27) -> 136.18 | F24: =SUM(Weekly!L28:L53) -> 186.18 | G24: =SUM(Weekly!L2:L53) -> 322.36
A25: Total P&L ($) | E25: =SUM(E22:E24) -> 1689.18 | F25: =SUM(F22:F24) -> 2735.18 | G25: =SUM(G22:G24) -> 4424.36
A26: Trades opened | E26: =SUM(Weekly!G2:G27) -> 42 | F26: =SUM(Weekly!G28:G53) -> 51 | G26: =SUM(Weekly!G2:G53) -> 93
A27: Weeks that hit 1% or more | E27: =COUNTIF(Weekly!Q2:Q27,"Yes") -> 15 | F27: =COUNTIF(Weekly!Q28:Q53,"Yes") -> 11 | G27: =COUNTIF(Weekly!Q2:Q53,"Yes") -> 26
A28: Up weeks | E28: =COUNTIF(Weekly!O2:O27,">0") -> 23 | F28: =COUNTIF(Weekly!O28:O53,">0") -> 23 | G28: =COUNTIF(Weekly!O2:O53,">0") -> 46
A29: Down weeks | E29: =COUNTIF(Weekly!O2:O27,"<0") -> 3 | F29: =COUNTIF(Weekly!O28:O53,"<0") -> 3 | G29: =COUNTIF(Weekly!O2:O53,"<0") -> 6
A30: Best week % | E30: =MAX(Weekly!P2:P27) -> 0.062575261 | F30: =MAX(Weekly!P28:P53) -> 0.10148152 | G30: =MAX(Weekly!P2:P53) -> 0.10148152
A31: Worst week % | E31: =MIN(Weekly!P2:P27) -> -0.11632 | F31: =MIN(Weekly!P28:P53) -> -0.037056796 | G31: =MIN(Weekly!P2:P53) -> -0.11632
A32: Puts assigned | E32: =COUNTIFS(Trades!B2:B94,"<=26",Trades!L2:L94,"Assigned") -> 2 | F32: =COUNTIFS(Trades!B2:B94,">26",Trades!L2:L94,"Assigned") -> 2 | G32: =COUNTIF(Trades!L2:L94,"Assigned") -> 4
A33: Calls called away | E33: =COUNTIFS(Trades!B2:B94,"<=26",Trades!L2:L94,"Called away") -> 2 | F33: =COUNTIFS(Trades!B2:B94,">26",Trades!L2:L94,"Called away") -> 2 | G33: =COUNTIF(Trades!L2:L94,"Called away") -> 4
A35: How to read: Start/Week 26/Week 52 columns are snapshots; the last three columns are what happened during each period. Week 26 is the official cross-run comparison point; Week 52 is the full year.
A36: Benchmarks: buy-and-hold = $7,500 invested in SimQ at $63.80 and held. Cash-only = $7,500 left in cash at the APY. 1% target = starting cash compounded at the weekly target.
A37: Source: SimQ Run 2 books (run-002-state.json), simulated paper trading with simulated prices. Not real-market results.
A39: Run 1 vs Run 2 at Week 26 (same start, same rules, different market)
A40: Measure | B40: Run 1 (Week 26) | C40: Run 2 (Week 26) | D40: Change
A41: Account value ($) | B41: 6575.78 | C41: =C12 -> 9189.18 | D41: =C41-B41 -> 2613.4
A42: Return since start | B42: =B41/$C$5-1 -> -0.12322933 | C42: =C13 -> 0.225224 | D42: =C42-B42 -> 0.34845333
A43: Avg weekly return (compounded) | B43: =(B41/$C$5)^(1/26)-1 -> -0.0050452994 | C43: =E14 -> 0.0078430462 | D43: =C43-B43 -> 0.012888346
...

Sheet Trades
A1: Trade # | B1: Week | C1: Opened | D1: Type | E1: Strike | F1: SimQ at sale | G1: Cushion from spot | H1: Premium / share | I1: Premium in ($) | J1: Collateral or cover | K1: Premium % of collateral | L1: Outcome | M1: Buy-back / share | N1: Buy-back out ($) | O1: Net option P&L ($) | P1: SimQ Friday close | Q1: Share result
A2: 1 | B2: 1 | C2: Mon | D2: Put | E2: 56 | F2: 63.8 | G2: =(F2-E2)/F2 -> 0.12225705 | H2: 0.53 | I2: =H2*100 -> 53 | J2: =E2*100 -> 5600 | K2: =I2/J2 -> 0.0094642857 | L2: Bought to close | M2: 7.09 | N2: =M2*100 -> 709 | O2: =I2-N2 -> -656 | P2: 38.44
A3: 2 | B3: 1 | C3: Wed | D3: Put | E3: 41 | F3: 49.36 | G3: =(F3-E3)/F3 -> 0.16936791 | H3: 0.35 | I3: =H3*100 -> 35 | J3: =E3*100 -> 4100 | K3: =I3/J3 -> 0.0085365854 | L3: Assigned | M3: 0 | N3: =M3*100 -> 0 | O3: =I3-N3 -> 35 | P3: 38.44 | Q3: Bought 100 at $41
A4: 3 | B4: 2 | C4: Mon | D4: Put | E4: 25 | F4: 38.44 | G4: =(F4-E4)/F4 -> 0.3496358 | H4: 0.42 | I4: =H4*100 -> 42 | J4: =E4*100 -> 2500 | K4: =I4/J4 -> 0.0168 | L4: Bought to close | M4: 0.01 | N4: =M4*100 -> 1 | O4: =I4-N4 -> 41 | P4: 37.75
A5: 4 | B5: 2 | C5: Mon | D5: Call | E5: 45 | F5: 38.44 | G5: =(E5-F5)/F5 -> 0.17065557 | H5: 0.71 | I5: =H5*100 -> 71 | J5: 100 shares | K5: =I5/(F5*100) -> 0.018470343 | L5: Expired worthless | M5: 0 | N5: =M5*100 -> 0 | O5: =I5-N5 -> 71 | P5: 37.75
A6: 5 | B6: 3 | C6: Wed | D6: Call | E6: 42 | F6: 39.56 | G6: =(E6-F6)/F6 -> 0.061678463 | H6: 0.23 | I6: =H6*100 -> 23 | J6: 100 shares | K6: =I6/(F6*100) -> 0.0058139535 | L6: Expired worthless | M6: 0 | N6: =M6*100 -> 0 | O6: =I6-N6 -> 23 | P6: 36.53
A7: 6 | B7: 4 | C7: Mon | D7: Call | E7: 42 | F7: 36.53 | G7: =(E7-F7)/F7 -> 0.14973994 | H7: 0.22 | I7: =H7*100 -> 22 | J7: 100 shares | K7: =I7/(F7*100) -> 0.0060224473 | L7: Expired worthless | M7: 0 | N7: =M7*100 -> 0 | O7: =I7-N7 -> 22 | P7: 40.02
A8: 7 | B8: 4 | C8: Mon | D8: Put | E8: 29 | F8: 36.53 | G8: =(F8-E8)/F8 -> 0.20613195 | H8: 0.24 | I8: =H8*100 -> 24 | J8: =E8*100 -> 2900 | K8: =I8/J8 -> 0.0082758621 | L8: Expired worthless | M8: 0 | N8: =M8*100 -> 0 | O8: =I8-N8 -> 24 | P8: 40.02
A9: 8 | B9: 5 | C9: Mon | D9: Call | E9: 43 | F9: 40.02 | G9: =(E9-F9)/F9 -> 0.074462769 | H9: 0.76 | I9: =H9*100 -> 76 | J9: 100 shares | K9: =I9/(F9*100) -> 0.018990505 | L9: Bought to close | M9: 2.66 | N9: =M9*100 -> 266 | O9: =I9-N9 -> -190 | P9: 47.59
A10: 9 | B10: 5 | C10: Wed | D10: Call | E10: 44.5 | F10: 44.81 | G10: =(E10-F10)/F10 -> -0.0069180986 | H10: 1.59 | I10: =H10*100 -> 159 | J10: 100 shares | K10: =I10/(F10*100) -> 0.035483151 | L10: Called away | M10: 0 | N10: =M10*100 -> 0 | O10: =I10-N10 -> 159 | P10: 47.59 | Q10: Sold 100 at $44.5
A11: 10 | B11: 6 | C11: Mon | D11: Put | E11: 40 | F11: 47.59 | G11: =(F11-E11)/F11 -> 0.15948729 | H11: 0.46 | I11: =H11*100 -> 46 | J11: =E11*100 -> 4000 | K11: =I11/J11 -> 0.0115 | L11: Expired worthless | M11: 0 | N11: =M11*100 -> 0 | O11: =I11-N11 -> 46 | P11: 46.18
A12: 11 | B12: 7 | C12: Mon | D12: Put | E12: 36 | F12: 46.18 | G12: =(F12-E12)/F12 -> 0.22044175 | H12: 0.34 | I12: =H12*100 -> 34 | J12: =E12*100 -> 3600 | K12: =I12/J12 -> 0.0094444444 | L12: Bought to close | M12: 0.01 | N12: =M12*100 -> 1 | O12: =I12-N12 -> 33 | P12: 53.08
A13: 12 | B13: 7 | C13: Wed | D13: Put | E13: 44 | F13: 49.74 | G13: =(F13-E13)/F13 -> 0.11540008 | H13: 0.29 | I13: =H13*100 -> 29 | J13: =E13*100 -> 4400 | K13: =I13/J13 -> 0.0065909091 | L13: Expired worthless | M13: 0 | N13: =M13*100 -> 0 | O13: =I13-N13 -> 29 | P13: 53.08
A14: 13 | B14: 8 | C14: Mon | D14: Put | E14: 43 | F14: 53.08 | G14: =(F14-E14)/F14 -> 0.18990203 | H14: 0.49 | I14: =H14*100 -> 49 | J14: =E14*100 -> 4300 | K14: =I14/J14 -> 0.011395349 | L14: Expired worthless | M14: 0 | N14: =M14*100 -> 0 | O14: =I14-N14 -> 49 | P14: 55.21
A15: 14 | B15: 9 | C15: Mon | D15: Put | E15: 44 | F15: 55.21 | G15: =(F15-E15)/F15 -> 0.20304293 | H15: 0.87 | I15: =H15*100 -> 87 | J15: =E15*100 -> 4400 | K15: =I15/J15 -> 0.019772727 | L15: Bought to close | M15: 0.01 | N15: =M15*100 -> 1 | O15: =I15-N15 -> 86 | P15: 58.89
A16: 15 | B16: 9 | C16: Mon | D16: Put | E16: 32.5 | F16: 55.21 | G16: =(F16-E16)/F16 -> 0.41133853 | H16: 0.09 | I16: =H16*100 -> 9 | J16: =E16*100 -> 3250 | K16: =I16/J16 -> 0.0027692308 | L16: Bought to close | M16: 0.01 | N16: =M16*100 -> 1 | O16: =I16-N16 -> 8 | P16: 58.89
A17: 16 | B17: 10 | C17: Mon | D17: Put | E17: 51.5 | F17: 58.89 | G17: =(F17-E17)/F17 -> 0.1254882 | H17: 0.47 | I17: =H17*100 -> 47 | J17: =E17*100 -> 5150 | K17: =I17/J17 -> 0.0091262136 | L17: Bought to close | M17: 0.27 | N17: =M17*100 -> 27 | O17: =I17-N17 -> 20 | P17: 60.22
A18: 17 | B18: 10 | C18: Wed | D18: Put | E18: 54 | F18: 60.99 | G18: =(F18-E18)/F18 -> 0.11460895 | H18: 0.49 | I18: =H18*100 -> 49 | J18: =E18*100 -> 5400 | K18: =I18/J18 -> 0.0090740741 | L18: Expired worthless | M18: 0 | N18: =M18*100 -> 0 | O18: =I18-N18 -> 49 | P18: 60.22
A19: 18 | B19: 11 | C19: Mon | D19: Put | E19: 49 | F19: 60.22 | G19: =(F19-E19)/F19 -> 0.18631684 | H19: 0.68 | I19: =H19*100 -> 68 | J19: =E19*100 -> 4900 | K19: =I19/J19 -> 0.013877551 | L19: Bought to close | M19: 0.01 | N19: =M19*100 -> 1 | O19: =I19-N19 -> 67 | P19: 66.23
A20: 19 | B20: 11 | C20: Wed | D20: Put | E20: 58 | F20: 65.88 | G20: =(F20-E20)/F20 -> 0.11961141 | H20: 0.21 | I20: =H20*100 -> 21 | J20: =E20*100 -> 5800 | K20: =I20/J20 -> 0.0036206897 | L20: Expired worthless | M20: 0 | N20: =M20*100 -> 0 | O20: =I20-N20 -> 21 | P20: 66.23
A21: 20 | B21: 12 | C21: Mon | D21: Put | E21: 56 | F21: 66.23 | G21: =(F21-E21)/F21 -> 0.15446172 | H21: 0.57 | I21: =H21*100 -> 57 | J21: =E21*100 -> 5600 | K21: =I21/J21 -> 0.010178571 | L21: Bought to close | M21: 0.02 | N21: =M21*100 -> 2 | O21: =I21-N21 -> 55 | P21: 67.1
A22: 21 | B22: 13 | C22: Mon | D22: Put | E22: 59 | F22: 67.1 | G22: =(F22-E22)/F22 -> 0.12071535 | H22: 0.6 | I22: =H22*100 -> 60 | J22: =E22*100 -> 5900 | K22: =I22/J22 -> 0.010169492 | L22: Bought to close | M22: 0.44 | N22: =M22*100 -> 44 | O22: =I22-N22 -> 16 | P22: 66.69
... A27: 26 | B27: 15 | C27: Wed | D27: Put | E27: 70 | F27: 74.45 | G27: =(F27-E27)/F27 -> 0.059771659 | H27: 0.36 | I27: =H27*100 -> 36 | J27: =E27*100 -> 7000 | K27: =I27/J27 -> 0.0051428571 | L27: Expired worthless | M27: 0 | N27: =M27*100 -> 0 | O27: =I27-N27 -> 36 | P27: 78.18
A28: 27 | B28: 16 | C28: Wed | D28: Put | E28: 75 | F28: 81.51 | G28: =(F28-E28)/F28 -> 0.079867501 | H28: 0.16 | I28: =H28*100 -> 16 | J28: =E28*100 -> 7500 | K28: =I28/J28 -> 0.0021333333 | L28: Assigned | M28: 0 | N28: =M28*100 -> 0 | O28: =I28-N28 -> 16 | P28: 71.26 | Q28: Bought 100 at $75
A29: 28 | B29: 17 | C29: Mon | D29: Call | E29: 76 | F29: 71.26 | G29: =(E29-F29)/F29 -> 0.06651698 | H29: 0.7 | I29: =H29*100 -> 70 | J29: 100 shares | K29: =I29/(F29*100) -> 0.0098231827 | L29: Expired worthless | M29: 0 | N29: =M29*100 -> 0 | O29: =I29-N29 -> 70 | P29: 72.04
A30: 29 | B30: 18 | C30: Mon | D30: Call | E30: 76 | F30: 72.04 | G30: =(E30-F30)/F30 -> 0.054969461 | H30: 0.99 | I30: =H30*100 -> 99 | J30: 100 shares | K30: =I30/(F30*100) -> 0.013742365 | L30: Called away | M30: 0 | N30: =M30*100 -> 0 | O30: =I30-N30 -> 99 | P30: 76.41 | Q30: Sold 100 at $76
A31: 30 | B31: 19 | C31: Mon | D31: Put | E31: 67 | F31: 76.41 | G31: =(F31-E31)/F31 -> 0.12315142 | H31: 0.65 | I31: =H31*100 -> 65 | J31: =E31*100 -> 6700 | K31: =I31/J31 -> 0.0097014925 | L31: Bought to close | M31: 0.21 | N31: =M31*100 -> 21 | O31: =I31-N31 -> 44 | P31: 83.96
A32: 31 | B32: 19 | C32: Wed | D32: Put | E32: 72 | F32: 80.44 | G32: =(F32-E32)/F32 -> 0.10492292 | H32: 0.61 | I32: =H32*100 -> 61 | J32: =E32*100 -> 7200 | K32: =I32/J32 -> 0.0084722222 | L32: Expired worthless | M32: 0 | N32: =M32*100 -> 0 | O32: =I32-N32 -> 61 | P32: 83.96
A33: 32 | B33: 20 | C33: Mon | D33: Put | E33: 69 | F33: 83.96 | G33: =(F33-E33)/F33 -> 0.17818009 | H33: 1.02 | I33: =H33*100 -> 102 | J33: =E33*100 -> 6900 | K33: =I33/J33 -> 0.014782609 | L33: Expired worthless | M33: 0 | N33: =M33*100 -> 0 | O33: =I33-N33 -> 102 | P33: 75.32
A34: 33 | B34: 21 | C34: Mon | D34: Put | E34: 56 | F34: 75.32 | G34: =(F34-E34)/F34 -> 0.25650558 | H34: 0.66 | I34: =H34*100 -> 66 | J34: =E34*100 -> 5600 | K34: =I34/J34 -> 0.011785714 | L34: Bought to close | M34: 0.01 | N34: =M34*100 -> 1 | O34: =I34-N34 -> 65 | P34: 74.38
A35: 34 | B35: 21 | C35: Wed | D35: Put | E35: 63 | F35: 70.79 | G35: =(F35-E35)/F35 -> 0.11004379 | H35: 0.17 | I35: =H35*100 -> 17 | J35: =E35*100 -> 6300 | K35: =I35/J35 -> 0.0026984127 | L35: Expired worthless | M35: 0 | N35: =M35*100 -> 0 | O35: =I35-N35 -> 17 | P35: 74.38
A36: 35 | B36: 22 | C36: Mon | D36: Put | E36: 65.5 | F36: 74.38 | G36: =(F36-E36)/F36 -> 0.11938693 | H36: 0.64 | I36: =H36*100 -> 64 | J36: =E36*100 -> 6550 | K36: =I36/J36 -> 0.0097709924 | L36: Bought to close | M36: 0.18 | N36: =M36*100 -> 18 | O36: =I36-N36 -> 46 | P36: 89.56
A37: 36 | B37: 22 | C37: Wed | D37: Put | E37: 70.5 | F37: 80.93 | G37: =(F37-E37)/F37 -> 0.12887681 | H37: 0.5 | I37: =H37*100 -> 50 | J37: =E37*100 -> 7050 | K37: =I37/J37 -> 0.0070921986 | L37: Expired worthless | M37: 0 | N37: =M37*100 -> 0 | O37: =I37-N37 -> 50 | P37: 89.56
A38: 37 | B38: 23 | C38: Mon | D38: Put | E38: 75 | F38: 89.56 | G38: =(F38-E38)/F38 -> 0.16257258 | H38: 1.11 | I38: =H38*100 -> 111 | J38: =E38*100 -> 7500 | K38: =I38/J38 -> 0.0148 | L38: Bought to close | M38: 0.96 | N38: =M38*100 -> 96 | O38: =I38-N38 -> 15 | P38: 78.9
A39: 38 | B39: 23 | C39: Wed | D39: Put | E39: 73.5 | F39: 85.65 | G39: =(F39-E39)/F39 -> 0.14185639 | H39: 0.71 | I39: =H39*100 -> 71 | J39: =E39*100 -> 7350 | K39: =I39/J39 -> 0.0096598639 | L39: Expired worthless | M39: 0 | N39: =M39*100 -> 0 | O39: =I39-N39 -> 71 | P39: 78.9
A40: 39 | B40: 24 | C40: Mon | D40: Put | E40: 64 | F40: 78.9 | G40: =(F40-E40)/F40 -> 0.18884664 | H40: 0.91 | I40: =H40*100 -> 91 | J40: =E40*100 -> 6400 | K40: =I40/J40 -> 0.01421875 | L40: Expired worthless | M40: 0 | N40: =M40*100 -> 0 | O40: =I40-N40 -> 91 | P40: 77.25
A41: 40 | B41: 25 | C41: Mon | D41: Put | E41: 66 | F41: 77.25 | G41: =(F41-E41)/F41 -> 0.14563107 | H41: 0.43 | I41: =H41*100 -> 43 | J41: =E41*100 -> 6600 | K41: =I41/J41 -> 0.0065151515 | L41: Expired worthless | M41: 0 | N41: =M41*100 -> 0 | O41: =I41-N41 -> 43 | P41: 79.89
A42: 41 | B42: 26 | C42: Mon | D42: Put | E42: 65 | F42: 79.89 | G42: =(F42-E42)/F42 -> 0.18638127 | H42: 0.72 | I42: =H42*100 -> 72 | J42: =E42*100 -> 6500 | K42: =I42/J42 -> 0.011076923 | L42: Bought to close | M42: 0.09 | N42: =M42*100 -> 9 | O42: =I42-N42 -> 63 | P42: 92.15
... A50: 49 | B50: 31 | C50: Mon | D50: Put | E50: 73 | F50: 81.16 | G50: =(F50-E50)/F50 -> 0.10054214 | H50: 0.72 | I50: =H50*100 -> 72 | J50: =E50*100 -> 7300 | K50: =I50/J50 -> 0.0098630137 | L50: Bought to close | M50: 1.42 | N50: =M50*100 -> 142 | O50: =I50-N50 -> -70 | P50: 69.78
A51: 50 | B51: 31 | C51: Wed | D51: Put | E51: 71 | F51: 75.71 | G51: =(F51-E51)/F51 -> 0.062211069 | H51: 0.83 | I51: =H51*100 -> 83 | J51: =E51*100 -> 7100 | K51: =I51/J51 -> 0.011690141 | L51: Assigned | M51: 0 | N51: =M51*100 -> 0 | O51: =I51-N51 -> 83 | P51: 69.78 | Q51: Bought 100 at $71
...

Sheet Weekly
A1: Week | B1: Regime (revealed Fri) | C1: SimQ Mon open | D1: SimQ Fri close | E1: SimQ week % | F1: Actions taken | G1: Trades opened | H1: Premium in ($) | I1: Buy-backs out ($) | J1: Options net ($) | K1: Share P&L ($) | L1: Interest ($) | M1: Account start ($) | N1: Account end ($) | O1: Week P&L ($) | P1: Week % | Q1: Hit 1%? | R1: Cumulative return | S1: 1% weekly target path ($) | T1: Ahead / behind target ($) | U1: Shares held Fri | V1: Buy-and-hold value ($) | W1: Cash-only value ($)
A2: 1 | B2: crash | C2: 63.8 | D2: 38.44 | E2: =D2/C2-1 -> -0.39749216 | F2: Mon: sold P56 @0.53; Wed: bought back P56 @7.09; Wed: sold P41 @0.35; Fri: P41 assigned | G2: =COUNTIF(Trades!$B$2:$B$94,A2) -> 2 | H2: =SUMIF(Trades!$B$2:$B$94,A2,Trades!$I$2:$I$94) -> 88 | I2: =SUMIF(Trades!$B$2:$B$94,A2,Trades!$N$2:$N$94) -> 709 | J2: =H2-I2 -> -621 | K2: -256 | L2: 4.6 | M2: =Summary!$C$5 -> 7500 | N2: =M2+J2+K2+L2 -> 6627.6 | O2: =N2-M2 -> -872.4 | P2: =O2/M2 -> -0.11632 | Q2: =IF(P2>=Summary!$C$7,"Yes","No") -> No | R2: =N2/Summary!$C$5-1 -> -0.11632 | S2: =Summary!$C$5*(1+Summary!$C$7)^A2 -> 7575 | T2: =N2-S2 -> -947.4 | U2: 100 | V2: =Summary!$C$5*D2/Summary!$C$8 -> 4518.8088 | W2: =Summary!$C$5*(1+Summary!$C$6*7*A2/365) -> 7505.7534
A3: 2 | B3: chop | C3: 38.44 | D3: 37.75 | E3: =D3/C3-1 -> -0.017950052 | F3: Mon: sold P25 @0.42; Mon: sold C45 @0.71; Wed: bought back P25 @0.01; Fri: C45 expired worthless | G3: =COUNTIF(Trades!$B$2:$B$94,A3) -> 2 | H3: =SUMIF(Trades!$B$2:$B$94,A3,Trades!$I$2:$I$94) -> 113 | I3: =SUMIF(Trades!$B$2:$B$94,A3,Trades!$N$2:$N$94) -> 1 | J3: =H3-I3 -> 112 | K3: -69 | L3: 2.22 | M3: =N2 -> 6627.6 | N3: =M3+J3+K3+L3 -> 6672.82 | O3: =N3-M3 -> 45.22 | P3: =O3/M3 -> 0.0068229827 | Q3: =IF(P3>=Summary!$C$7,"Yes","No") -> No | R3: =N3/Summary!$C$5-1 -> -0.11029067 | S3: =Summary!$C$5*(1+Summary!$C$7)^A3 -> 7650.75 | T3: =N3-S3 -> -977.93 | U3: 100 | V3: =Summary!$C$5*D3/Summary!$C$8 -> 4437.6959 | W3: =Summary!$C$5*(1+Summary!$C$6*7*A3/365) -> 7511.5068
A4: 3 | B4: chop | C4: 37.75 | D4: 36.53 | E4: =D4/C4-1 -> -0.032317881 | F4: Mon: pass/hold; Wed: sold C42 @0.23; Fri: C42 expired worthless | G4: =COUNTIF(Trades!$B$2:$B$94,A4) -> 1 | H4: =SUMIF(Trades!$B$2:$B$94,A4,Trades!$I$2:$I$94) -> 23 | I4: =SUMIF(Trades!$B$2:$B$94,A4,Trades!$N$2:$N$94) -> 0 | J4: =H4-I4 -> 23 | K4: -122 | L4: 2.23 | M4: =N3 -> 6672.82 | N4: =M4+J4+K4+L4 -> 6576.05 | O4: =N4-M4 -> -96.77 | P4: =O4/M4 -> -0.014502115 | Q4: =IF(P4>=Summary!$C$7,"Yes","No") -> No | R4: =N4/Summary!$C$5-1 -> -0.12319333 | S4: =Summary!$C$5*(1+Summary!$C$7)^A4 -> 7727.2575 | T4: =N4-S4 -> -1151.2075 | U4: 100 | V4: =Summary!$C$5*D4/Summary!$C$8 -> 4294.279 | W4: =Summary!$C$5*(1+Summary!$C$6*7*A4/365) -> 7517.2603
A5: 4 | B5: rebound | C5: 36.53 | D5: 40.02 | E5: =D5/C5-1 -> 0.095537914 | F5: Mon: sold C42 @0.22; Mon: sold P29 @0.24; Wed: pass/hold; Fri: C42 expired worthless; Fri: P29 expired worthless | G5: =COUNTIF(Trades!$B$2:$B$94,A5) -> 2 | H5: =SUMIF(Trades!$B$2:$B$94,A5,Trades!$I$2:$I$94) -> 46 | I5: =SUMIF(Trades!$B$2:$B$94,A5,Trades!$N$2:$N$94) -> 0 | J5: =H5-I5 -> 46 | K5: 349 | L5: 2.28 | M5: =N4 -> 6576.05 | N5: =M5+J5+K5+L5 -> 6973.33 | O5: =N5-M5 -> 397.28 | P5: =O5/M5 -> 0.060413166 | Q5: =IF(P5>=Summary!$C$7,"Yes","No") -> Yes | R5: =N5/Summary!$C$5-1 -> -0.070222667 | S5: =Summary!$C$5*(1+Summary!$C$7)^A5 -> 7804.5301 | T5: =N5-S5 -> -831.20008 | U5: 100 | V5: =Summary!$C$5*D5/Summary!$C$8 -> 4704.5455 | W5: =Summary!$C$5*(1+Summary!$C$6*7*A5/365) -> 7523.0137
A6: 5 | B6: rebound | C6: 40.02 | D6: 47.59 | E6: =D6/C6-1 -> 0.18915542 | F6: Mon: sold C43 @0.76; Wed: bought back C43 @2.66; Wed: sold C44.5 @1.59; Fri: C44.5 called away | G6: =COUNTIF(Trades!$B$2:$B$94,A6) -> 2 | H6: =SUMIF(Trades!$B$2:$B$94,A6,Trades!$I$2:$I$94) -> 235 | I6: =SUMIF(Trades!$B$2:$B$94,A6,Trades!$N$2:$N$94) -> 266 | J6: =H6-I6 -> -31 | K6: 448 | L6: 3.27 | M6: =N5 -> 6973.33 | N6: =M6+J6+K6+L6 -> 7393.6 | O6: =N6-M6 -> 420.27 | P6: =O6/M6 -> 0.060268193 | Q6: =IF(P6>=Summary!$C$7,"Yes","No") -> Yes | R6: =N6/Summary!$C$5-1 -> -0.014186667 | S6: =Summary!$C$5*(1+Summary!$C$7)^A6 -> 7882.5754 | T6: =N6-S6 -> -488.97538 | U6: 0 | V6: =Summary!$C$5*D6/Summary!$C$8 -> 5594.4357 | W6: =Summary!$C$5*(1+Summary!$C$6*7*A6/365) -> 7528.7671
A7: 6 | B7: selloff | C7: 47.59 | D7: 46.18 | E7: =D7/C7-1 -> -0.029628073 | F7: Mon: sold P40 @0.46; Wed: pass/hold; Fri: P40 expired worthless | G7: =COUNTIF(Trades!$B$2:$B$94,A7) -> 1 | H7: =SUMIF(Trades!$B$2:$B$94,A7,Trades!$I$2:$I$94) -> 46 | I7: =SUMIF(Trades!$B$2:$B$94,A7,Trades!$N$2:$N$94) -> 0 | J7: =H7-I7 -> 46 | K7: 0 | L7: 5.71 | M7: =N6 -> 7393.6 | N7: =M7+J7+K7+L7 -> 7445.31 | O7: =N7-M7 -> 51.71 | P7: =O7/M7 -> 0.0069938866 | Q7: =IF(P7>=Summary!$C$7,"Yes","No") -> No | R7: =N7/Summary!$C$5-1 -> -0.007292 | S7: =Summary!$C$5*(1+Summary!$C$7)^A7 -> 7961.4011 | T7: =N7-S7 -> -516.09113 | U7: 0 | V7: =Summary!$C$5*D7/Summary!$C$8 -> 5428.6834 | W7: =Summary!$C$5*(1+Summary!$C$6*7*A7/365) -> 7534.5205
A8: 7 | B8: selloff | C8: 46.18 | D8: 53.08 | E8: =D8/C8-1 -> 0.14941533 | F8: Mon: sold P36 @0.34; Wed: bought back P36 @0.01; Wed: sold P44 @0.29; Fri: P44 expired worthless | G8: =COUNTIF(Trades!$B$2:$B$94,A8) -> 2 | H8: =SUMIF(Trades!$B$2:$B$94,A8,Trades!$I$2:$I$94) -> 63 | I8: =SUMIF(Trades!$B$2:$B$94,A8,Trades!$N$2:$N$94) -> 1 | J8: =H8-I8 -> 62 | K8: 0 | L8: 5.75 | M8: =N7 -> 7445.31 | N8: =M8+J8+K8+L8 -> 7513.06 | O8: =N8-M8 -> 67.75 | P8: =O8/M8 -> 0.0090996883 | Q8: =IF(P8>=Summary!$C$7,"Yes","No") -> No | R8: =N8/Summary!$C$5-1 -> 0.0017413333 | S8: =Summary!$C$5*(1+Summary!$C$7)^A8 -> 8041.0151 | T8: =N8-S8 -> -527.95514 | U8: 0 | V8: =Summary!$C$5*D8/Summary!$C$8 -> 6239.8119 | W8: =Summary!$C$5*(1+Summary!$C$6*7*A8/365) -> 7540.274
A9: 8 | B9: crash | C9: 53.08 | D9: 55.21 | E9: =D9/C9-1 -> 0.040128109 | F9: Mon: sold P43 @0.49; Wed: pass/hold; Fri: P43 expired worthless | G9: =COUNTIF(Trades!$B$2:$B$94,A9) -> 1 | H9: =SUMIF(Trades!$B$2:$B$94,A9,Trades!$I$2:$I$94) -> 49 | I9: =SUMIF(Trades!$B$2:$B$94,A9,Trades!$N$2:$N$94) -> 0 | J9: =H9-I9 -> 49 | K9: 0 | L9: 5.8 | M9: =N8 -> 7513.06 | N9: =M9+J9+K9+L9 -> 7567.86 | O9: =N9-M9 -> 54.8 | P9: =O9/M9 -> 0.0072939654 | Q9: =IF(P9>=Summary!$C$7,"Yes","No") -> No | R9: =N9/Summary!$C$5-1 -> 0.009048 | S9: =Summary!$C$5*(1+Summary!$C$7)^A9 -> 8121.4253 | T9: =N9-S9 -> -553.56529 | U9: 0 | V9: =Summary!$C$5*D9/Summary!$C$8 -> 6490.2038 | W9: =Summary!$C$5*(1+Summary!$C$6*7*A9/365) -> 7546.0274
A10: 9 | B10: chop | C10: 55.21 | D10: 58.89 | E10: =D10/C10-1 -> 0.066654592 | F10: Mon: sold P44 @0.87; Mon: sold P32.5 @0.09; Wed: bought back P44 @0.01; Wed: bought back P32.5 @0.01 | G10: =COUNTIF(Trades!$B$2:$B$94,A10) -> 2 | H10: =SUMIF(Trades!$B$2:$B$94,A10,Trades!$I$2:$I$94) -> 96 | I10: =SUMIF(Trades!$B$2:$B$94,A10,Trades!$N$2:$N$94) -> 2 | J10: =H10-I10 -> 94 | K10: 0 | L10: 5.88 | M10: =N9 -> 7567.86 | N10: =M10+J10+K10+L10 -> 7667.74 | O10: =N10-M10 -> 99.88 | P10: =O10/M10 -> 0.013197919 | Q10: =IF(P10>=Summary!$C$7,"Yes","No") -> Yes | R10: =N10/Summary!$C$5-1 -> 0.022365333 | S10: =Summary!$C$5*(1+Summary!$C$7)^A10 -> 8202.6395 | T10: =N10-S10 -> -534.89955 | U10: 0 | V10: =Summary!$C$5*D10/Summary!$C$8 -> 6922.8056 | W10: =Summary!$C$5*(1+Summary!$C$6*7*A10/365) -> 7551.7808
A11: 10 | B11: selloff | C11: 58.89 | D11: 60.22 | E11: =D11/C11-1 -> 0.02258448 | F11: Mon: sold P51.5 @0.47; Wed: bought back P51.5 @0.27; Wed: sold P54 @0.49; Fri: P54 expired worthless | G11: =COUNTIF(Trades!$B$2:$B$94,A11) -> 2 | H11: =SUMIF(Trades!$B$2:$B$94,A11,Trades!$I$2:$I$94) -> 96 | I11: =SUMIF(Trades!$B$2:$B$94,A11,Trades!$N$2:$N$94) -> 27 | J11: =H11-I11 -> 69 | K11: 0 | L11: 5.93 | M11: =N10 -> 7667.74 | N11: =M11+J11+K11+L11 -> 7742.67 | O11: =N11-M11 -> 74.93 | P11: =O11/M11 -> 0.0097721102 | Q11: =IF(P11>=Summary!$C$7,"Yes","No") -> No | R11: =N11/Summary!$C$5-1 -> 0.032356 | S11: =Summary!$C$5*(1+Summary!$C$7)^A11 -> 8284.6659 | T11: =N11-S11 -> -541.99594 | U11: 0 | V11: =Summary!$C$5*D11/Summary!$C$8 -> 7079.1536 | W11: =Summary!$C$5*(1+Summary!$C$6*7*A11/365) -> 7557.5342
A12: 11 | B12: rebound | C12: 60.22 | D12: 66.23 | E12: =D12/C12-1 -> 0.099800731 | F12: Mon: sold P49 @0.68; Wed: bought back P49 @0.01; Wed: sold P58 @0.21; Fri: P58 expired worthless | G12: =COUNTIF(Trades!$B$2:$B$94,A12) -> 2 | H12: =SUMIF(Trades!$B$2:$B$94,A12,Trades!$I$2:$I$94) -> 89 | I12: =SUMIF(Trades!$B$2:$B$94,A12,Trades!$N$2:$N$94) -> 1 | J12: =H12-I12 -> 88 | K12: 0 | L12: 6 | M12: =N11 -> 7742.67 | N12: =M12+J12+K12+L12 -> 7836.67 | O12: =N12-M12 -> 94 | P12: =O12/M12 -> 0.012140515 | Q12: =IF(P12>=Summary!$C$7,"Yes","No") -> Yes | R12: =N12/Summary!$C$5-1 -> 0.044889333 | S12: =Summary!$C$5*(1+Summary!$C$7)^A12 -> 8367.5126 | T12: =N12-S12 -> -530.8426 | U12: 0 | V12: =Summary!$C$5*D12/Summary!$C$8 -> 7785.6583 | W12: =Summary!$C$5*(1+Summary!$C$6*7*A12/365) -> 7563.2877
A13: 12 | B13: chop | C13: 66.23 | D13: 67.1 | E13: =D13/C13-1 -> 0.013136041 | F13: Mon: sold P56 @0.57; Wed: bought back P56 @0.02 | G13: =COUNTIF(Trades!$B$2:$B$94,A13) -> 1 | H13: =SUMIF(Trades!$B$2:$B$94,A13,Trades!$I$2:$I$94) -> 57 | I13: =SUMIF(Trades!$B$2:$B$94,A13,Trades!$N$2:$N$94) -> 2 | J13: =H13-I13 -> 55 | K13: 0 | L13: 6.05 | M13: =N12 -> 7836.67 | N13: =M13+J13+K13+L13 -> 7897.72 | O13: =N13-M13 -> 61.05 | P13: =O13/M13 -> 0.0077902987 | Q13: =IF(P13>=Summary!$C$7,"Yes","No") -> No | R13: =N13/Summary!$C$5-1 -> 0.053029333 | S13: =Summary!$C$5*(1+Summary!$C$7)^A13 -> 8451.1877 | T13: =N13-S13 -> -553.46773 | U13: 0 | V13: =Summary!$C$5*D13/Summary!$C$8 -> 7887.931 | W13: =Summary!$C$5*(1+Summary!$C$6*7*A13/365) -> 7569.0411
A14: 13 | B14: chop | C14: 67.1 | D14: 66.69 | E14: =D14/C14-1 -> -0.0061102832 | F14: Mon: sold P59 @0.60; Wed: bought back P59 @0.44; Wed: sold P57 @0.19; Fri: P57 expired worthless | G14: =COUNTIF(Trades!$B$2:$B$94,A14) -> 2 | H14: =SUMIF(Trades!$B$2:$B$94,A14,Trades!$I$2:$I$94) -> 79 | I14: =SUMIF(Trades!$B$2:$B$94,A14,Trades!$N$2:$N$94) -> 44 | J14: =H14-I14 -> 35 | K14: 0 | L14: 6.09 | M14: =N13 -> 7897.72 | N14: =M14+J14+K14+L14 -> 7938.81 | O14: =N14-M14 -> 41.09 | P14: =O14/M14 -> 0.0052027674 | Q14: =IF(P14>=Summary!$C$7,"Yes","No") -> No | R14: =N14/Summary!$C$5-1 -> 0.058508 | S14: =Summary!$C$5*(1+Summary!$C$7)^A14 -> 8535.6996 | T14: =N14-S14 -> -596.8896 | U14: 0 | V14: =Summary!$C$5*D14/Summary!$C$8 -> 7839.7335 | W14: =Summary!$C$5*(1+Summary!$C$6*7*A14/365) -> 7574.7945
... A53: 52 | B53: selloff | C53: 72.85 | D53: 64.67 | E53: =D53/C53-1 -> -0.11228552 | F53: Mon: sold P56 @0.95; Mon: sold P57 @1.07; Wed: bought back P56 @0.03; Wed: bought back P57 @0.04; Wed: sold P60 @0.08; Fri: P60 expired worthless | G53: =COUNTIF(Trades!$B$2:$B$94,A53) -> 3 | H53: =SUMIF(Trades!$B$2:$B$94,A53,Trades!$I$2:$I$94) -> 210 | I53: =SUMIF(Trades!$B$2:$B$94,A53,Trades!$N$2:$N$94) -> 7 | J53: =H53-I53 -> 203 | K53: 0 | L53: 9.14 | M53: =N52 -> 11712.22 | N53: =M53+J53+K53+L53 -> 11924.36 | O53: =N53-M53 -> 212.14 | P53: =O53/M53 -> 0.018112706 | Q53: =IF(P53>=Summary!$C$7,"Yes","No") -> Yes | R53: =N53/Summary!$C$5-1 -> 0.58991467 | S53: =Summary!$C$5*(1+Summary!$C$7)^A53 -> 12582.667 | T53: =N53-S53 -> -658.30691 | U53: 0 | V53: =Summary!$C$5*D53/Summary!$C$8 -> 7602.2727 | W53: =Summary!$C$5*(1+Summary!$C$6*7*A53/365) -> 7799.1781
A55: Blue = recorded data from the run (prices, regime, share P&L, interest, shares held). Black = formulas. Green = link to Summary sheet.
A56: Share P&L = stock gain/loss that week from assignments, called-away sales and the Friday mark on shares held. Week 26 and Week 52 rows are shaded.
A57: Source: SimQ Run 2 books (run-002-state.json / run-002-ledger.md), simulated paper trading; regime is hidden during the week and revealed at Friday close.
